<?xml version='1.0'?>

<robot name="mybot" xmlns:xacro="http://www.ros.org/wiki/xacro">

<xacro:include filename="$(find mybot_description)/urdf/mybot.gazebo" />
<xacro:include filename="$(find mybot_description)/urdf/materials.xacro" />
<xacro:include filename="$(find mybot_description)/urdf/macro.xacro" />

  <link name="chassis">
    <pose>0 0 0.1 0 0 0</pose>
    <inertial>
      <mass value="10.0"/>
      <origin xyz="0.0 0 0.1" rpy=" 0 0 0"/>
      <inertia
          ixx="0.09" ixy="0" ixz="0"
          iyy="0.09" iyz="0"
          izz="0.09"
      />
    </inertial>

    <collision name='collision'>
      <geometry>
        <box size=".4 .2 .1"/>
      </geometry>
    </collision>

    <visual name='chassis_visual'>
      <origin xyz="0 0 0" rpy=" 0 0 0"/>
      <geometry>
        <box size=".4 .2 .1"/>
      </geometry>
    </visual>
  </link>


  <link name="left_wheel">
    <collision name="collision">
      <origin xyz="0 0 0" rpy="0 1.5707 1.5707"/>
      <geometry>
        <cylinder radius="0.1" length="0.05"/>
      </geometry>
    </collision>
    <visual name="left_wheel_visual">
      <origin xyz="0 0 0" rpy="0 1.5707 1.5707"/>
      <geometry>
        <cylinder radius="0.1" length="0.05"/>
      </geometry>
    </visual>
    <inertial>
      <origin xyz="0 0 0" rpy="0 1.5707 1.5707"/>
      <mass value="5"/>
      <cylinder_inertia m="5" r="0.1" h="0.05"/>
      <inertia
        ixx="0.013" ixy="0.0" ixz="0.0"
        iyy="0.013" iyz="0.0"
        izz="0.013"/>
    </inertial>
  </link>


  <link name="right_wheel">
    <collision name="collision">
      <origin xyz="0 0 0" rpy="0 1.5707 1.5707"/>
      <geometry>
        <cylinder radius="0.1" length="0.05"/>
      </geometry>
    </collision>
    <visual name="right_wheel_visual">
      <origin xyz="0 0 0" rpy="0 1.5707 1.5707"/>
      <geometry>
        <cylinder radius="0.1" length="0.05"/>
      </geometry>
    </visual>
    <inertial>
      <origin xyz="0 0 0" rpy="0 1.5707 1.5707"/>
      <mass value="5"/>
      <cylinder_inertia m="5" r="0.1" h="0.05"/>
      <inertia
        ixx="0.013" ixy="0.0" ixz="0.0"
        iyy="0.013" iyz="0.0"
        izz="0.013"/>
    </inertial>
  </link>


  <link name="left_fwheel">
    <collision name="collision">
      <origin xyz="0 0 0" rpy="0 1.5707 1.5707"/>
      <geometry>
        <cylinder radius="0.1" length="0.05"/>
      </geometry>
    </collision>
    <visual name="left_wheel_fvisual">
      <origin xyz="0 0 0" rpy="0 1.5707 1.5707"/>
      <geometry>
        <cylinder radius="0.1" length="0.05"/>
      </geometry>
    </visual>
    <inertial>
      <origin xyz="0 0 0" rpy="0 1.5707 1.5707"/>
      <mass value="5"/>
      <cylinder_inertia m="5" r="0.1" h="0.05"/>
      <inertia
        ixx="0.013" ixy="0.0" ixz="0.0"
        iyy="0.013" iyz="0.0"
        izz="0.013"/>
    </inertial>
  </link>


  <link name="right_fwheel">
    <collision name="collision">
      <origin xyz="0 0 0" rpy="0 1.5707 1.5707"/>
      <geometry>
        <cylinder radius="0.1" length="0.05"/>
      </geometry>
    </collision>
    <visual name="right_wheel_fvisual">
      <origin xyz="0 0 0" rpy="0 1.5707 1.5707"/>
      <geometry>
        <cylinder radius="0.1" length="0.05"/>
      </geometry>
    </visual>
    <inertial>
      <origin xyz="0 0 0" rpy="0 1.5707 1.5707"/>
      <mass value="5"/>
      <cylinder_inertia m="5" r="0.1" h="0.05"/>
      <inertia
        ixx="0.013" ixy="0.0" ixz="0.0"
        iyy="0.013" iyz="0.0"
        izz="0.013"/>
    </inertial>
  </link>

  <joint type="continuous" name="left_wheel_hinge">
    <origin xyz="0.1 0.15 0" rpy="0 0 0"/>
    <child link="left_wheel"/>
    <parent link="chassis"/>
    <axis xyz="0 1 0" rpy="0 0 0"/>
    <limit effort="100" velocity="100"/>
    <joint_properties damping="0.0" friction="1.0"/>
  </joint>

  <joint type="continuous" name="right_wheel_hinge">
    <origin xyz="0.1 -0.15 0" rpy="0 0 0"/>
    <child link="right_wheel"/>
    <parent link="chassis"/>
    <axis xyz="0 1 0" rpy="0 0 0"/>
    <limit effort="100" velocity="100"/>
    <joint_properties damping="0.0" friction="1.0"/>
  </joint>




 <joint type="continuous" name="left_wheel_fhinge">
    <origin xyz="-0.11 0.15 0" rpy="0 0 0"/>
    <child link="left_fwheel"/>
    <parent link="chassis"/>
    <axis xyz="0 1 0" rpy="0 0 0"/>
    <limit effort="100" velocity="100"/>
    <joint_properties damping="0.0" friction="1.0"/>
  </joint>

  <joint type="continuous" name="right_wheel_fhinge">
    <origin xyz="-0.1 -0.15 0" rpy="0 0 0"/>
    <child link="right_fwheel"/>
    <parent link="chassis"/>
    <axis xyz="0 1 0" rpy="0 0 0"/>
    <limit effort="100" velocity="100"/>
    <joint_properties damping="0.0" friction="1"/>
  </joint>

<!--========================== Link for laser 1 ========================= -->
  
  <!-- Link for laser -->
  <link name="sensor_laser_1">
    <inertial>
      <origin xyz="0 0 0" rpy="0 0 0" />
      <mass value="0.1" />
      <xacro:cylinder_inertia mass="0.5" r="0.01" l="0.05" />
    </inertial>

    <visual>
      <origin xyz="0 0 0" rpy="0 0 0" />
      <geometry>
        <cylinder radius="0.01" length="0.05"/>
      </geometry>
      <material name="orange" />
      <material name="laserLight" />
    </visual>

    <collision>
      <origin xyz="0 0 0" rpy="0 0 0"/>
      <geometry>
        <cylinder radius="0.01" length="0.05"/>
      </geometry>
      <material name="collisionLaser" />
    </collision>
  </link>

  <!--========================== Link for laser 2 ========================= -->
  

  <link name="sensor_laser_2">
    <inertial>
      <origin xyz="0 0 0" rpy="0 0 0" />
      <mass value="0.1" />
      <xacro:cylinder_inertia mass="0.5" r="0.01" l="0.05" />
    </inertial>

    <visual>
      <origin xyz="0 0 0" rpy="0 0 0" />
      <geometry>
        <cylinder radius="0.01" length="0.05"/>
      </geometry>
      <material name="orange" />
      <material name="laserLight" />
    </visual>

    <collision>
      <origin xyz="0 0 0" rpy="0 0 0"/>
      <geometry>
        <cylinder radius="0.01" length="0.05"/>
      </geometry>
      <material name="collisionLaser" />
    </collision>
  </link>

  <!--========================== Link for laser 3 ========================= -->
  
  <link name="sensor_laser_3">
    <inertial>
      <origin xyz="0 0 0" rpy="0 0 0" />
      <mass value="0.1" />
      <xacro:cylinder_inertia mass="0.5" r="0.01" l="0.05" />
    </inertial>

    <visual>
      <origin xyz="0 0 0" rpy="0 0 0" />
      <geometry>
        <cylinder radius="0.01" length="0.05"/>
      </geometry>
      <material name="orange" />
      <material name="laserLight" />
    </visual>

    <collision>
      <origin xyz="0 0 0" rpy="0 0 0"/>
      <geometry>
        <cylinder radius="0.01" length="0.05"/>
      </geometry>
      <material name="collisionLaser" />
    </collision>
  </link>

<!--========================== Link for laser 4 ========================= -->

<link name="sensor_laser_4">
  <inertial>
    <origin xyz="0 0 0" rpy="0 0 0" />
    <mass value="0.1" />
    <xacro:cylinder_inertia mass="0.5" r="0.01" l="0.05" />
  </inertial>
  <visual>
    <origin xyz="0 0 0" rpy="0 0 0" />
    <geometry>
      <cylinder radius="0.01" length="0.05"/>
    </geometry>
    <material name="orange" />
    <material name="laserLight" />
  </visual>
  <collision>
    <origin xyz="0 0 0" rpy="0 0 0"/>
    <geometry>
      <cylinder radius="0.01" length="0.05"/>
    </geometry>
    <material name="collisionLaser" />
  </collision>
</link>



<!--========================== Link for laser 5 ========================= -->

<link name="sensor_laser_5">
  <inertial>
    <origin xyz="0 0 0" rpy="0 0 0" />
    <mass value="0.1" />
    <xacro:cylinder_inertia mass="0.5" r="0.01" l="0.05" />
  </inertial>

  <visual>
    <origin xyz="0 0 0" rpy="0 0 0" />
    <geometry>
      <cylinder radius="0.01" length="0.05"/>
    </geometry>
    <material name="orange" />
    <material name="laserLight" />
  </visual>

  <collision>
    <origin xyz="0 0 0" rpy="0 0 0"/>
    <geometry>
      <cylinder radius="0.01" length="0.05"/>
    </geometry>
    <material name="collisionLaser" />
  </collision>
</link>






<link name="imu_link">
  <inertial>
    <origin xyz="0 0 0" rpy="0 0 0" />
    <mass value="4" />
    <xacro:cylinder_inertia mass="0.5" r="0.05" l="0.1" />
  </inertial>
  <visual>
    <origin xyz="0 0 0" rpy="0 0 0" />
    <geometry>
      <cylinder radius="0.05" length="0.1"/>
    </geometry>
    <material name="white" />
  </visual>
  <collision>
    <origin xyz="0 0 0" rpy="0 0 0"/>
    <geometry>
      <cylinder radius="0.01" length="0.05"/>
    </geometry>
    <material name="collisionLaser" />
  </collision>

</link> 

<joint name="joint_imu" type="fixed">
  <origin xyz="-0.08 0 0.07" rpy="0 0 0"/>
  <parent link="chassis"/>
  <child link="imu_link"/>
</joint> 


  <!-- Joint for laser -->
  <joint name="joint_sensor_laser_1" type="fixed">
    <origin xyz="0.28 0 0.07" rpy="0 0 0"/>
    <parent link="chassis"/>
    <child link="sensor_laser_1"/>
  </joint>


<!-- Joint for laser -->
  <joint name="joint_sensor_laser_2" type="fixed">
    <origin xyz="0.23 0.1 0.07" rpy="0 0 0"/>
    <parent link="chassis"/>
    <child link="sensor_laser_2"/>
  </joint>
<!-- Joint for laser -->
<joint name="joint_sensor_laser_3" type="fixed">
  <origin xyz="0.2 0.18 0.07" rpy="0 0 0"/>
  <parent link="chassis"/>
  <child link="sensor_laser_3"/>
</joint>

<!-- Joint for laser -->
<joint name="joint_sensor_laser_4" type="fixed">
  <origin xyz="0.23 -0.1 0.07" rpy="0 0 0"/>
  <parent link="chassis"/>
  <child link="sensor_laser_4"/>
</joint>

<!-- Joint for laser -->
<joint name="joint_sensor_laser_5" type="fixed">
  <origin xyz="0.2 -0.18 0.07" rpy="0 0 0"/>
  <parent link="chassis"/>
  <child link="sensor_laser_5"/>
</joint>

</robot>
